<?xml version="1.0" ?>
<!--rosrun gazebo_ros spawn_model -file ~/Simulation/src/diff_drive_description/urdf/diff_drive.urdf -urdf -x 1 -model diff_drive-->
<!--rosrun teleop_twist_keyboard teleop_twist_keyboard.py-->
<robot name="RoboBot" xmlns:xacro="https://www.ros.org/wiki/xacro" >

    <gazebo reference="left_wheel">
      <material>Gazebo/Turquoise</material>
    </gazebo>
    <gazebo reference="right_wheel">
      <material>Gazebo/Turquoise</material>
    </gazebo>
   <!--<gazebo reference="chassis">
      <material>
       <script>
          <uri>materials://scripts/repeated.material</uri>
          <name>Template/Blue</name>
        </script>

      </material>
    </gazebo> -->

    <gazebo>
      <plugin filename="libgazebo_ros_diff_drive.so" name="differential_drive_controller">
        <legacyMode>false</legacyMode>
        <alwaysOn>true</alwaysOn>
        <updateRate>20</updateRate>
        <leftJoint>left_wheel_joint</leftJoint>
        <rightJoint>right_wheel_joint</rightJoint>
        <wheelSeparation>0.2</wheelSeparation>
        <wheelDiameter>0.2</wheelDiameter>
        <torque>0.2</torque>
        <commandTopic>cmd_vel</commandTopic>
        <odometryTopic>odom</odometryTopic>
        <odometryFrame>odom</odometryFrame>
        <robotBaseFrame>chassis</robotBaseFrame>
      </plugin>
    </gazebo>


    <link name="chassis">
      <pose>0 0 0.1 0 0 0</pose>
      <inertial>
        <mass value="5"/>
        <origin rpy="0 0 0" xyz="0 0 0.1"/>
        <inertia ixx="0.0395" ixy="0" ixz="0" iyy="0.1062" iyz="0" izz="0.1062"/>
      </inertial>

      <collision>
        <geometry>
          <box size="0.5 0.3 0.07"/>
        </geometry>
      </collision>

      <visual>
        <origin rpy="0 0 0" xyz="0 0 0"/>
        <geometry>
          <box size="0.5 0.3 0.07"/>
        </geometry>
      </visual>

      <collision >
        <origin rpy=" 0 0 0" xyz="0.35 0 -0.05"/>
        <geometry>
          <sphere radius="0.05"/>
        </geometry>
        <surface>
          <friction>
            <ode>
              <mu>0</mu>
              <mu2>0</mu2>
              <slip1>1.0</slip1>
              <slip2>1.0</slip2>
            </ode>
          </friction>
        </surface>
      </collision>

      <visual>
        <origin rpy=" 0 0 0" xyz="0.2 0 -0.05"/>
        <geometry>
          <sphere radius="0.05"/>
        </geometry>
      </visual>

    </link>
    <link name="right_wheel">
      <inertial>
        <mass value="0.2"/>
        <origin rpy="0 1.5707 1.5707" xyz="0 0 0"/>
        <inertia ixx="0.0005" ixy="0" ixz="0" iyy="0.0005" iyz="0" izz="0.001"/>
      </inertial>

      <collision>
        <origin rpy="0 1.5707 1.5707" xyz="0 0 0"/>
        <geometry>
          <cylinder length="0.04" radius="0.1"/>
        </geometry>
      </collision>

      <visual>
        <origin rpy="0 1.5707 1.5707" xyz="0 0 0"/>
        <geometry>
          <cylinder length="0.04" radius="0.1"/>
        </geometry>

      </visual>

    </link>


    <link name="left_wheel">
      <inertial>
        <mass value="0.2"/>
        <origin rpy="0 1.5707 1.5707" xyz="0 0 0"/>
        <inertia ixx="0.0005" ixy="0" ixz="0" iyy="0.0005" iyz="0" izz="0.001"/>
      </inertial>

      <collision>
        <origin rpy="0 1.5707 1.5707" xyz="0 0 0"/>
        <geometry>
          <cylinder length="0.04" radius="0.1"/>
        </geometry>
      </collision>

      <visual>
        <origin rpy="0 1.5707 1.5707" xyz="0 0 0"/>
        <geometry>
          <cylinder length="0.04" radius="0.1"/>
        </geometry>
      </visual>

    </link>
    <joint type="continuous" name="right_wheel_joint">
      <origin rpy="0 0 0" xyz="-0.05 0.15 0"/>
      <child link="right_wheel"/>
      <parent link="chassis"/>
      <axis rpy="0 0 0" xyz="0 1 0"/>
    </joint>

    <joint type="continuous" name="left_wheel_joint" >
      <origin rpy="0 0 0" xyz="-0.05 -0.15 0"/>
      <child link="left_wheel"/>
      <parent link="chassis"/>
      <axis rpy="0 0 0" xyz="0 1 0"/>
    </joint>
  </robot>
